2025-08-06 11:48:23,064 | INFO     | __main__ | üöÄ –ë–æ—Ç –∑–∞–ø—É—â–µ–Ω‚Ä¶
2025-08-06 11:48:28,978 | ERROR    | __main__ | Exception while handling update Update(message=Message(channel_chat_created=False, chat=Chat(first_name='No?', id=1169418620, last_name='Where?', type=<ChatType.PRIVATE>, username='nekodro4'), date=datetime.datetime(2025, 8, 6, 11, 48, 28, tzinfo=datetime.timezone.utc), delete_chat_photo=False, entities=(MessageEntity(length=6, offset=0, type=<MessageEntityType.BOT_COMMAND>),), from_user=User(first_name='No?', id=1169418620, is_bot=False, language_code='ru', last_name='Where?', username='nekodro4'), group_chat_created=False, message_id=88, supergroup_chat_created=False, text='/start'), update_id=680449752)
Traceback (most recent call last):
  File "/root/akm_bot/venv/lib/python3.12/site-packages/telegram/ext/_application.py", line 1311, in process_update
    await coroutine
  File "/root/akm_bot/venv/lib/python3.12/site-packages/telegram/ext/_handlers/basehandler.py", line 158, in handle_update
    return await self.callback(update, context)
           ^^^^^^^^^^^^^^^^^^^^^^^^^^^^^^^^^^^^
  File "/root/akm_bot/bot.py", line 85, in start
    await context.bot.set_chat_menu_button(
  File "/root/akm_bot/venv/lib/python3.12/site-packages/telegram/ext/_extbot.py", line 3555, in set_chat_menu_button
    return await super().set_chat_menu_button(
           ^^^^^^^^^^^^^^^^^^^^^^^^^^^^^^^^^^^
  File "/root/akm_bot/venv/lib/python3.12/site-packages/telegram/_bot.py", line 8369, in set_chat_menu_button
    return await self._post(
           ^^^^^^^^^^^^^^^^^
  File "/root/akm_bot/venv/lib/python3.12/site-packages/telegram/_bot.py", line 698, in _post
    return await self._do_post(
           ^^^^^^^^^^^^^^^^^^^^
  File "/root/akm_bot/venv/lib/python3.12/site-packages/telegram/ext/_extbot.py", line 370, in _do_post
    return await super()._do_post(
           ^^^^^^^^^^^^^^^^^^^^^^^
  File "/root/akm_bot/venv/lib/python3.12/site-packages/telegram/_bot.py", line 727, in _do_post
    result = await request.post(
             ^^^^^^^^^^^^^^^^^^^
  File "/root/akm_bot/venv/lib/python3.12/site-packages/telegram/request/_baserequest.py", line 197, in post
    result = await self._request_wrapper(
             ^^^^^^^^^^^^^^^^^^^^^^^^^^^^
  File "/root/akm_bot/venv/lib/python3.12/site-packages/telegram/request/_baserequest.py", line 374, in _request_wrapper
    raise exception
telegram.error.BadRequest: Can't parse menu button: field "web_app" must be of type object
2025-08-06 11:48:45,929 | ERROR    | __main__ | –û—à–∏–±–∫–∞ –æ–±—Ä–∞–±–æ—Ç–∫–∏ –∑–∞—è–≤–∫–∏: PdfString.to_unicode() takes 1 positional argument but 2 were given
Traceback (most recent call last):
  File "/root/akm_bot/bot.py", line 112, in handle_web_app_data
    fill_pdf("template.pdf", pdf_path, data)
  File "/root/akm_bot/fill_pdf.py", line 12, in fill_pdf
    key = key_raw.decode('utf-8') if hasattr(key_raw, 'decode') else str(key_raw)
          ^^^^^^^^^^^^^^^^^^^^^^^
TypeError: PdfString.to_unicode() takes 1 positional argument but 2 were given
2025-08-06 11:59:54,870 | INFO     | __main__ | üöÄ –ë–æ—Ç –∑–∞–ø—É—â–µ–Ω‚Ä¶
2025-08-06 11:59:59,973 | ERROR    | __main__ | Exception while handling update Update(message=Message(channel_chat_created=False, chat=Chat(first_name='No?', id=1169418620, last_name='Where?', type=<ChatType.PRIVATE>, username='nekodro4'), date=datetime.datetime(2025, 8, 6, 11, 59, 59, tzinfo=datetime.timezone.utc), delete_chat_photo=False, entities=(MessageEntity(length=6, offset=0, type=<MessageEntityType.BOT_COMMAND>),), from_user=User(first_name='No?', id=1169418620, is_bot=False, language_code='ru', last_name='Where?', username='nekodro4'), group_chat_created=False, message_id=91, supergroup_chat_created=False, text='/start'), update_id=680449754)
Traceback (most recent call last):
  File "/root/akm_bot/venv/lib/python3.12/site-packages/telegram/ext/_application.py", line 1311, in process_update
    await coroutine
  File "/root/akm_bot/venv/lib/python3.12/site-packages/telegram/ext/_handlers/basehandler.py", line 158, in handle_update
    return await self.callback(update, context)
           ^^^^^^^^^^^^^^^^^^^^^^^^^^^^^^^^^^^^
  File "/root/akm_bot/bot.py", line 92, in start
    await context.bot.set_chat_menu_button(
  File "/root/akm_bot/venv/lib/python3.12/site-packages/telegram/ext/_extbot.py", line 3555, in set_chat_menu_button
    return await super().set_chat_menu_button(
           ^^^^^^^^^^^^^^^^^^^^^^^^^^^^^^^^^^^
  File "/root/akm_bot/venv/lib/python3.12/site-packages/telegram/_bot.py", line 8369, in set_chat_menu_button
    return await self._post(
           ^^^^^^^^^^^^^^^^^
  File "/root/akm_bot/venv/lib/python3.12/site-packages/telegram/_bot.py", line 698, in _post
    return await self._do_post(
           ^^^^^^^^^^^^^^^^^^^^
  File "/root/akm_bot/venv/lib/python3.12/site-packages/telegram/ext/_extbot.py", line 370, in _do_post
    return await super()._do_post(
           ^^^^^^^^^^^^^^^^^^^^^^^
  File "/root/akm_bot/venv/lib/python3.12/site-packages/telegram/_bot.py", line 727, in _do_post
    result = await request.post(
             ^^^^^^^^^^^^^^^^^^^
  File "/root/akm_bot/venv/lib/python3.12/site-packages/telegram/request/_baserequest.py", line 197, in post
    result = await self._request_wrapper(
             ^^^^^^^^^^^^^^^^^^^^^^^^^^^^
  File "/root/akm_bot/venv/lib/python3.12/site-packages/telegram/request/_baserequest.py", line 374, in _request_wrapper
    raise exception
telegram.error.BadRequest: Can't parse menu button: field "web_app" must be of type object
2025-08-06 12:03:45,090 | INFO     | __main__ | üöÄ –ë–æ—Ç –∑–∞–ø—É—â–µ–Ω‚Ä¶
2025-08-06 12:04:24,505 | ERROR    | root | –û—à–∏–±–∫–∞ –æ—Ç–ø—Ä–∞–≤–∫–∏ –ø–∏—Å—å–º–∞: (535, b'5.7.0 NEOBHODIM parol prilozheniya https://help.mail.ru/mail/security/protection/external / Application password is REQUIRED')
Traceback (most recent call last):
  File "/root/akm_bot/email_sender.py", line 23, in send_email
    smtp.login(FROM_EMAIL, EMAIL_PASSWORD)
  File "/usr/lib/python3.12/smtplib.py", line 750, in login
    raise last_exception
  File "/usr/lib/python3.12/smtplib.py", line 739, in login
    (code, resp) = self.auth(
                   ^^^^^^^^^^
  File "/usr/lib/python3.12/smtplib.py", line 662, in auth
    raise SMTPAuthenticationError(code, resp)
smtplib.SMTPAuthenticationError: (535, b'5.7.0 NEOBHODIM parol prilozheniya https://help.mail.ru/mail/security/protection/external / Application password is REQUIRED')
2025-08-06 12:04:24,774 | INFO     | __main__ | –ó–∞—è–≤–∫–∞ output/form_1169418620_20250806120422.pdf –æ—Ç–ø—Ä–∞–≤–ª–µ–Ω–∞
2025-08-06 12:18:42,503 | INFO     | __main__ | üöÄ –ë–æ—Ç –∑–∞–ø—É—â–µ–Ω‚Ä¶
2025-08-06 12:19:05,079 | INFO     | __main__ | –ó–∞—è–≤–∫–∞ output/form_1169418620_20250806121903.pdf –æ—Ç–ø—Ä–∞–≤–ª–µ–Ω–∞
2025-08-07 11:46:03,085 | INFO     | __main__ | üöÄ –ë–æ—Ç –∑–∞–ø—É—â–µ–Ω‚Ä¶
2025-08-07 11:47:05,073 | INFO     | __main__ | –ó–∞—è–≤–∫–∞ output/form_1169418620_20250807114704.pdf –æ—Ç–ø—Ä–∞–≤–ª–µ–Ω–∞
2025-08-07 15:24:52,288 | INFO     | __main__ | üöÄ –ë–æ—Ç –∑–∞–ø—É—â–µ–Ω‚Ä¶
2025-08-07 15:25:31,319 | INFO     | __main__ | –ó–∞—è–≤–∫–∞ output/form_1169418620_20250807152530.pdf –æ—Ç–ø—Ä–∞–≤–ª–µ–Ω–∞
2025-08-07 15:34:21,369 | INFO     | __main__ | üöÄ –ë–æ—Ç –∑–∞–ø—É—â–µ–Ω‚Ä¶
2025-08-07 15:36:27,588 | INFO     | __main__ | üöÄ –ë–æ—Ç –∑–∞–ø—É—â–µ–Ω‚Ä¶
2025-08-07 15:36:57,711 | INFO     | __main__ | –ó–∞—è–≤–∫–∞ output/form_1169418620_20250807153656.pdf –æ—Ç–ø—Ä–∞–≤–ª–µ–Ω–∞
2025-08-07 15:42:59,763 | INFO     | __main__ | üöÄ –ë–æ—Ç –∑–∞–ø—É—â–µ–Ω‚Ä¶
2025-08-07 15:43:00,231 | ERROR    | __main__ | Exception while handling update None
Traceback (most recent call last):
  File "/root/akm_bot/venv/lib/python3.12/site-packages/telegram/ext/_utils/networkloop.py", line 115, in network_retry_loop
    if not await do_action():
           ^^^^^^^^^^^^^^^^^
  File "/root/akm_bot/venv/lib/python3.12/site-packages/telegram/ext/_utils/networkloop.py", line 108, in do_action
    return action_cb_task.result()
           ^^^^^^^^^^^^^^^^^^^^^^^
  File "/root/akm_bot/venv/lib/python3.12/site-packages/telegram/ext/_updater.py", line 340, in polling_action_cb
    updates = await self.bot.get_updates(
              ^^^^^^^^^^^^^^^^^^^^^^^^^^^
  File "/root/akm_bot/venv/lib/python3.12/site-packages/telegram/ext/_extbot.py", line 670, in get_updates
    updates = await super().get_updates(
              ^^^^^^^^^^^^^^^^^^^^^^^^^^
  File "/root/akm_bot/venv/lib/python3.12/site-packages/telegram/_bot.py", line 4611, in get_updates
    await self._post(
  File "/root/akm_bot/venv/lib/python3.12/site-packages/telegram/_bot.py", line 698, in _post
    return await self._do_post(
           ^^^^^^^^^^^^^^^^^^^^
  File "/root/akm_bot/venv/lib/python3.12/site-packages/telegram/ext/_extbot.py", line 370, in _do_post
    return await super()._do_post(
           ^^^^^^^^^^^^^^^^^^^^^^^
  File "/root/akm_bot/venv/lib/python3.12/site-packages/telegram/_bot.py", line 727, in _do_post
    result = await request.post(
             ^^^^^^^^^^^^^^^^^^^
  File "/root/akm_bot/venv/lib/python3.12/site-packages/telegram/request/_baserequest.py", line 197, in post
    result = await self._request_wrapper(
             ^^^^^^^^^^^^^^^^^^^^^^^^^^^^
  File "/root/akm_bot/venv/lib/python3.12/site-packages/telegram/request/_baserequest.py", line 374, in _request_wrapper
    raise exception
telegram.error.Conflict: Conflict: terminated by other getUpdates request; make sure that only one bot instance is running
2025-08-07 15:43:04,287 | ERROR    | __main__ | Exception while handling update None
Traceback (most recent call last):
  File "/root/akm_bot/venv/lib/python3.12/site-packages/telegram/ext/_utils/networkloop.py", line 115, in network_retry_loop
    if not await do_action():
           ^^^^^^^^^^^^^^^^^
  File "/root/akm_bot/venv/lib/python3.12/site-packages/telegram/ext/_utils/networkloop.py", line 108, in do_action
    return action_cb_task.result()
           ^^^^^^^^^^^^^^^^^^^^^^^
  File "/root/akm_bot/venv/lib/python3.12/site-packages/telegram/ext/_updater.py", line 340, in polling_action_cb
    updates = await self.bot.get_updates(
              ^^^^^^^^^^^^^^^^^^^^^^^^^^^
  File "/root/akm_bot/venv/lib/python3.12/site-packages/telegram/ext/_extbot.py", line 670, in get_updates
    updates = await super().get_updates(
              ^^^^^^^^^^^^^^^^^^^^^^^^^^
  File "/root/akm_bot/venv/lib/python3.12/site-packages/telegram/_bot.py", line 4611, in get_updates
    await self._post(
  File "/root/akm_bot/venv/lib/python3.12/site-packages/telegram/_bot.py", line 698, in _post
    return await self._do_post(
           ^^^^^^^^^^^^^^^^^^^^
  File "/root/akm_bot/venv/lib/python3.12/site-packages/telegram/ext/_extbot.py", line 370, in _do_post
    return await super()._do_post(
           ^^^^^^^^^^^^^^^^^^^^^^^
  File "/root/akm_bot/venv/lib/python3.12/site-packages/telegram/_bot.py", line 727, in _do_post
    result = await request.post(
             ^^^^^^^^^^^^^^^^^^^
  File "/root/akm_bot/venv/lib/python3.12/site-packages/telegram/request/_baserequest.py", line 197, in post
    result = await self._request_wrapper(
             ^^^^^^^^^^^^^^^^^^^^^^^^^^^^
  File "/root/akm_bot/venv/lib/python3.12/site-packages/telegram/request/_baserequest.py", line 374, in _request_wrapper
    raise exception
telegram.error.Conflict: Conflict: terminated by other getUpdates request; make sure that only one bot instance is running
2025-08-07 15:43:05,342 | ERROR    | __main__ | Exception while handling update None
Traceback (most recent call last):
  File "/root/akm_bot/venv/lib/python3.12/site-packages/telegram/ext/_utils/networkloop.py", line 115, in network_retry_loop
    if not await do_action():
           ^^^^^^^^^^^^^^^^^
  File "/root/akm_bot/venv/lib/python3.12/site-packages/telegram/ext/_utils/networkloop.py", line 108, in do_action
    return action_cb_task.result()
           ^^^^^^^^^^^^^^^^^^^^^^^
  File "/root/akm_bot/venv/lib/python3.12/site-packages/telegram/ext/_updater.py", line 340, in polling_action_cb
    updates = await self.bot.get_updates(
              ^^^^^^^^^^^^^^^^^^^^^^^^^^^
  File "/root/akm_bot/venv/lib/python3.12/site-packages/telegram/ext/_extbot.py", line 670, in get_updates
    updates = await super().get_updates(
              ^^^^^^^^^^^^^^^^^^^^^^^^^^
  File "/root/akm_bot/venv/lib/python3.12/site-packages/telegram/_bot.py", line 4611, in get_updates
    await self._post(
  File "/root/akm_bot/venv/lib/python3.12/site-packages/telegram/_bot.py", line 698, in _post
    return await self._do_post(
           ^^^^^^^^^^^^^^^^^^^^
  File "/root/akm_bot/venv/lib/python3.12/site-packages/telegram/ext/_extbot.py", line 370, in _do_post
    return await super()._do_post(
           ^^^^^^^^^^^^^^^^^^^^^^^
  File "/root/akm_bot/venv/lib/python3.12/site-packages/telegram/_bot.py", line 727, in _do_post
    result = await request.post(
             ^^^^^^^^^^^^^^^^^^^
  File "/root/akm_bot/venv/lib/python3.12/site-packages/telegram/request/_baserequest.py", line 197, in post
    result = await self._request_wrapper(
             ^^^^^^^^^^^^^^^^^^^^^^^^^^^^
  File "/root/akm_bot/venv/lib/python3.12/site-packages/telegram/request/_baserequest.py", line 374, in _request_wrapper
    raise exception
telegram.error.Conflict: Conflict: terminated by other getUpdates request; make sure that only one bot instance is running
2025-08-07 15:43:09,901 | ERROR    | __main__ | Exception while handling update None
Traceback (most recent call last):
  File "/root/akm_bot/venv/lib/python3.12/site-packages/telegram/ext/_utils/networkloop.py", line 115, in network_retry_loop
    if not await do_action():
           ^^^^^^^^^^^^^^^^^
  File "/root/akm_bot/venv/lib/python3.12/site-packages/telegram/ext/_utils/networkloop.py", line 108, in do_action
    return action_cb_task.result()
           ^^^^^^^^^^^^^^^^^^^^^^^
  File "/root/akm_bot/venv/lib/python3.12/site-packages/telegram/ext/_updater.py", line 340, in polling_action_cb
    updates = await self.bot.get_updates(
              ^^^^^^^^^^^^^^^^^^^^^^^^^^^
  File "/root/akm_bot/venv/lib/python3.12/site-packages/telegram/ext/_extbot.py", line 670, in get_updates
    updates = await super().get_updates(
              ^^^^^^^^^^^^^^^^^^^^^^^^^^
  File "/root/akm_bot/venv/lib/python3.12/site-packages/telegram/_bot.py", line 4611, in get_updates
    await self._post(
  File "/root/akm_bot/venv/lib/python3.12/site-packages/telegram/_bot.py", line 698, in _post
    return await self._do_post(
           ^^^^^^^^^^^^^^^^^^^^
  File "/root/akm_bot/venv/lib/python3.12/site-packages/telegram/ext/_extbot.py", line 370, in _do_post
    return await super()._do_post(
           ^^^^^^^^^^^^^^^^^^^^^^^
  File "/root/akm_bot/venv/lib/python3.12/site-packages/telegram/_bot.py", line 727, in _do_post
    result = await request.post(
             ^^^^^^^^^^^^^^^^^^^
  File "/root/akm_bot/venv/lib/python3.12/site-packages/telegram/request/_baserequest.py", line 197, in post
    result = await self._request_wrapper(
             ^^^^^^^^^^^^^^^^^^^^^^^^^^^^
  File "/root/akm_bot/venv/lib/python3.12/site-packages/telegram/request/_baserequest.py", line 374, in _request_wrapper
    raise exception
telegram.error.Conflict: Conflict: terminated by other getUpdates request; make sure that only one bot instance is running
2025-08-07 15:43:11,459 | ERROR    | __main__ | Exception while handling update None
Traceback (most recent call last):
  File "/root/akm_bot/venv/lib/python3.12/site-packages/telegram/ext/_utils/networkloop.py", line 115, in network_retry_loop
    if not await do_action():
           ^^^^^^^^^^^^^^^^^
  File "/root/akm_bot/venv/lib/python3.12/site-packages/telegram/ext/_utils/networkloop.py", line 108, in do_action
    return action_cb_task.result()
           ^^^^^^^^^^^^^^^^^^^^^^^
  File "/root/akm_bot/venv/lib/python3.12/site-packages/telegram/ext/_updater.py", line 340, in polling_action_cb
    updates = await self.bot.get_updates(
              ^^^^^^^^^^^^^^^^^^^^^^^^^^^
  File "/root/akm_bot/venv/lib/python3.12/site-packages/telegram/ext/_extbot.py", line 670, in get_updates
    updates = await super().get_updates(
              ^^^^^^^^^^^^^^^^^^^^^^^^^^
  File "/root/akm_bot/venv/lib/python3.12/site-packages/telegram/_bot.py", line 4611, in get_updates
    await self._post(
  File "/root/akm_bot/venv/lib/python3.12/site-packages/telegram/_bot.py", line 698, in _post
    return await self._do_post(
           ^^^^^^^^^^^^^^^^^^^^
  File "/root/akm_bot/venv/lib/python3.12/site-packages/telegram/ext/_extbot.py", line 370, in _do_post
    return await super()._do_post(
           ^^^^^^^^^^^^^^^^^^^^^^^
  File "/root/akm_bot/venv/lib/python3.12/site-packages/telegram/_bot.py", line 727, in _do_post
    result = await request.post(
             ^^^^^^^^^^^^^^^^^^^
  File "/root/akm_bot/venv/lib/python3.12/site-packages/telegram/request/_baserequest.py", line 197, in post
    result = await self._request_wrapper(
             ^^^^^^^^^^^^^^^^^^^^^^^^^^^^
  File "/root/akm_bot/venv/lib/python3.12/site-packages/telegram/request/_baserequest.py", line 374, in _request_wrapper
    raise exception
telegram.error.Conflict: Conflict: terminated by other getUpdates request; make sure that only one bot instance is running
2025-08-07 15:43:16,766 | ERROR    | __main__ | Exception while handling update None
Traceback (most recent call last):
  File "/root/akm_bot/venv/lib/python3.12/site-packages/telegram/ext/_utils/networkloop.py", line 115, in network_retry_loop
    if not await do_action():
           ^^^^^^^^^^^^^^^^^
  File "/root/akm_bot/venv/lib/python3.12/site-packages/telegram/ext/_utils/networkloop.py", line 108, in do_action
    return action_cb_task.result()
           ^^^^^^^^^^^^^^^^^^^^^^^
  File "/root/akm_bot/venv/lib/python3.12/site-packages/telegram/ext/_updater.py", line 340, in polling_action_cb
    updates = await self.bot.get_updates(
              ^^^^^^^^^^^^^^^^^^^^^^^^^^^
  File "/root/akm_bot/venv/lib/python3.12/site-packages/telegram/ext/_extbot.py", line 670, in get_updates
    updates = await super().get_updates(
              ^^^^^^^^^^^^^^^^^^^^^^^^^^
  File "/root/akm_bot/venv/lib/python3.12/site-packages/telegram/_bot.py", line 4611, in get_updates
    await self._post(
  File "/root/akm_bot/venv/lib/python3.12/site-packages/telegram/_bot.py", line 698, in _post
    return await self._do_post(
           ^^^^^^^^^^^^^^^^^^^^
  File "/root/akm_bot/venv/lib/python3.12/site-packages/telegram/ext/_extbot.py", line 370, in _do_post
    return await super()._do_post(
           ^^^^^^^^^^^^^^^^^^^^^^^
  File "/root/akm_bot/venv/lib/python3.12/site-packages/telegram/_bot.py", line 727, in _do_post
    result = await request.post(
             ^^^^^^^^^^^^^^^^^^^
  File "/root/akm_bot/venv/lib/python3.12/site-packages/telegram/request/_baserequest.py", line 197, in post
    result = await self._request_wrapper(
             ^^^^^^^^^^^^^^^^^^^^^^^^^^^^
  File "/root/akm_bot/venv/lib/python3.12/site-packages/telegram/request/_baserequest.py", line 374, in _request_wrapper
    raise exception
telegram.error.Conflict: Conflict: terminated by other getUpdates request; make sure that only one bot instance is running
2025-08-07 15:43:19,073 | ERROR    | __main__ | Exception while handling update None
Traceback (most recent call last):
  File "/root/akm_bot/venv/lib/python3.12/site-packages/telegram/ext/_utils/networkloop.py", line 115, in network_retry_loop
    if not await do_action():
           ^^^^^^^^^^^^^^^^^
  File "/root/akm_bot/venv/lib/python3.12/site-packages/telegram/ext/_utils/networkloop.py", line 108, in do_action
    return action_cb_task.result()
           ^^^^^^^^^^^^^^^^^^^^^^^
  File "/root/akm_bot/venv/lib/python3.12/site-packages/telegram/ext/_updater.py", line 340, in polling_action_cb
    updates = await self.bot.get_updates(
              ^^^^^^^^^^^^^^^^^^^^^^^^^^^
  File "/root/akm_bot/venv/lib/python3.12/site-packages/telegram/ext/_extbot.py", line 670, in get_updates
    updates = await super().get_updates(
              ^^^^^^^^^^^^^^^^^^^^^^^^^^
  File "/root/akm_bot/venv/lib/python3.12/site-packages/telegram/_bot.py", line 4611, in get_updates
    await self._post(
  File "/root/akm_bot/venv/lib/python3.12/site-packages/telegram/_bot.py", line 698, in _post
    return await self._do_post(
           ^^^^^^^^^^^^^^^^^^^^
  File "/root/akm_bot/venv/lib/python3.12/site-packages/telegram/ext/_extbot.py", line 370, in _do_post
    return await super()._do_post(
           ^^^^^^^^^^^^^^^^^^^^^^^
  File "/root/akm_bot/venv/lib/python3.12/site-packages/telegram/_bot.py", line 727, in _do_post
    result = await request.post(
             ^^^^^^^^^^^^^^^^^^^
  File "/root/akm_bot/venv/lib/python3.12/site-packages/telegram/request/_baserequest.py", line 197, in post
    result = await self._request_wrapper(
             ^^^^^^^^^^^^^^^^^^^^^^^^^^^^
  File "/root/akm_bot/venv/lib/python3.12/site-packages/telegram/request/_baserequest.py", line 374, in _request_wrapper
    raise exception
telegram.error.Conflict: Conflict: terminated by other getUpdates request; make sure that only one bot instance is running
2025-08-07 15:43:22,507 | ERROR    | __main__ | Exception while handling update None
Traceback (most recent call last):
  File "/root/akm_bot/venv/lib/python3.12/site-packages/telegram/ext/_utils/networkloop.py", line 115, in network_retry_loop
    if not await do_action():
           ^^^^^^^^^^^^^^^^^
  File "/root/akm_bot/venv/lib/python3.12/site-packages/telegram/ext/_utils/networkloop.py", line 108, in do_action
    return action_cb_task.result()
           ^^^^^^^^^^^^^^^^^^^^^^^
  File "/root/akm_bot/venv/lib/python3.12/site-packages/telegram/ext/_updater.py", line 340, in polling_action_cb
    updates = await self.bot.get_updates(
              ^^^^^^^^^^^^^^^^^^^^^^^^^^^
  File "/root/akm_bot/venv/lib/python3.12/site-packages/telegram/ext/_extbot.py", line 670, in get_updates
    updates = await super().get_updates(
              ^^^^^^^^^^^^^^^^^^^^^^^^^^
  File "/root/akm_bot/venv/lib/python3.12/site-packages/telegram/_bot.py", line 4611, in get_updates
    await self._post(
  File "/root/akm_bot/venv/lib/python3.12/site-packages/telegram/_bot.py", line 698, in _post
    return await self._do_post(
           ^^^^^^^^^^^^^^^^^^^^
  File "/root/akm_bot/venv/lib/python3.12/site-packages/telegram/ext/_extbot.py", line 370, in _do_post
    return await super()._do_post(
           ^^^^^^^^^^^^^^^^^^^^^^^
  File "/root/akm_bot/venv/lib/python3.12/site-packages/telegram/_bot.py", line 727, in _do_post
    result = await request.post(
             ^^^^^^^^^^^^^^^^^^^
  File "/root/akm_bot/venv/lib/python3.12/site-packages/telegram/request/_baserequest.py", line 197, in post
    result = await self._request_wrapper(
             ^^^^^^^^^^^^^^^^^^^^^^^^^^^^
  File "/root/akm_bot/venv/lib/python3.12/site-packages/telegram/request/_baserequest.py", line 374, in _request_wrapper
    raise exception
telegram.error.Conflict: Conflict: terminated by other getUpdates request; make sure that only one bot instance is running
2025-08-07 15:43:25,482 | INFO     | __main__ | –ó–∞—è–≤–∫–∞ output/form_1169418620_20250807154324.pdf –æ—Ç–ø—Ä–∞–≤–ª–µ–Ω–∞
2025-08-07 15:43:25,941 | ERROR    | __main__ | Exception while handling update None
Traceback (most recent call last):
  File "/root/akm_bot/venv/lib/python3.12/site-packages/telegram/ext/_utils/networkloop.py", line 115, in network_retry_loop
    if not await do_action():
           ^^^^^^^^^^^^^^^^^
  File "/root/akm_bot/venv/lib/python3.12/site-packages/telegram/ext/_utils/networkloop.py", line 108, in do_action
    return action_cb_task.result()
           ^^^^^^^^^^^^^^^^^^^^^^^
  File "/root/akm_bot/venv/lib/python3.12/site-packages/telegram/ext/_updater.py", line 340, in polling_action_cb
    updates = await self.bot.get_updates(
              ^^^^^^^^^^^^^^^^^^^^^^^^^^^
  File "/root/akm_bot/venv/lib/python3.12/site-packages/telegram/ext/_extbot.py", line 670, in get_updates
    updates = await super().get_updates(
              ^^^^^^^^^^^^^^^^^^^^^^^^^^
  File "/root/akm_bot/venv/lib/python3.12/site-packages/telegram/_bot.py", line 4611, in get_updates
    await self._post(
  File "/root/akm_bot/venv/lib/python3.12/site-packages/telegram/_bot.py", line 698, in _post
    return await self._do_post(
           ^^^^^^^^^^^^^^^^^^^^
  File "/root/akm_bot/venv/lib/python3.12/site-packages/telegram/ext/_extbot.py", line 370, in _do_post
    return await super()._do_post(
           ^^^^^^^^^^^^^^^^^^^^^^^
  File "/root/akm_bot/venv/lib/python3.12/site-packages/telegram/_bot.py", line 727, in _do_post
    result = await request.post(
             ^^^^^^^^^^^^^^^^^^^
  File "/root/akm_bot/venv/lib/python3.12/site-packages/telegram/request/_baserequest.py", line 197, in post
    result = await self._request_wrapper(
             ^^^^^^^^^^^^^^^^^^^^^^^^^^^^
  File "/root/akm_bot/venv/lib/python3.12/site-packages/telegram/request/_baserequest.py", line 374, in _request_wrapper
    raise exception
telegram.error.Conflict: Conflict: terminated by other getUpdates request; make sure that only one bot instance is running
2025-08-07 15:43:29,997 | ERROR    | __main__ | Exception while handling update None
Traceback (most recent call last):
  File "/root/akm_bot/venv/lib/python3.12/site-packages/telegram/ext/_utils/networkloop.py", line 115, in network_retry_loop
    if not await do_action():
           ^^^^^^^^^^^^^^^^^
  File "/root/akm_bot/venv/lib/python3.12/site-packages/telegram/ext/_utils/networkloop.py", line 108, in do_action
    return action_cb_task.result()
           ^^^^^^^^^^^^^^^^^^^^^^^
  File "/root/akm_bot/venv/lib/python3.12/site-packages/telegram/ext/_updater.py", line 340, in polling_action_cb
    updates = await self.bot.get_updates(
              ^^^^^^^^^^^^^^^^^^^^^^^^^^^
  File "/root/akm_bot/venv/lib/python3.12/site-packages/telegram/ext/_extbot.py", line 670, in get_updates
    updates = await super().get_updates(
              ^^^^^^^^^^^^^^^^^^^^^^^^^^
  File "/root/akm_bot/venv/lib/python3.12/site-packages/telegram/_bot.py", line 4611, in get_updates
    await self._post(
  File "/root/akm_bot/venv/lib/python3.12/site-packages/telegram/_bot.py", line 698, in _post
    return await self._do_post(
           ^^^^^^^^^^^^^^^^^^^^
  File "/root/akm_bot/venv/lib/python3.12/site-packages/telegram/ext/_extbot.py", line 370, in _do_post
    return await super()._do_post(
           ^^^^^^^^^^^^^^^^^^^^^^^
  File "/root/akm_bot/venv/lib/python3.12/site-packages/telegram/_bot.py", line 727, in _do_post
    result = await request.post(
             ^^^^^^^^^^^^^^^^^^^
  File "/root/akm_bot/venv/lib/python3.12/site-packages/telegram/request/_baserequest.py", line 197, in post
    result = await self._request_wrapper(
             ^^^^^^^^^^^^^^^^^^^^^^^^^^^^
  File "/root/akm_bot/venv/lib/python3.12/site-packages/telegram/request/_baserequest.py", line 374, in _request_wrapper
    raise exception
telegram.error.Conflict: Conflict: terminated by other getUpdates request; make sure that only one bot instance is running
2025-08-07 15:43:35,225 | ERROR    | __main__ | Exception while handling update None
Traceback (most recent call last):
  File "/root/akm_bot/venv/lib/python3.12/site-packages/telegram/ext/_utils/networkloop.py", line 115, in network_retry_loop
    if not await do_action():
           ^^^^^^^^^^^^^^^^^
  File "/root/akm_bot/venv/lib/python3.12/site-packages/telegram/ext/_utils/networkloop.py", line 108, in do_action
    return action_cb_task.result()
           ^^^^^^^^^^^^^^^^^^^^^^^
  File "/root/akm_bot/venv/lib/python3.12/site-packages/telegram/ext/_updater.py", line 340, in polling_action_cb
    updates = await self.bot.get_updates(
              ^^^^^^^^^^^^^^^^^^^^^^^^^^^
  File "/root/akm_bot/venv/lib/python3.12/site-packages/telegram/ext/_extbot.py", line 670, in get_updates
    updates = await super().get_updates(
              ^^^^^^^^^^^^^^^^^^^^^^^^^^
  File "/root/akm_bot/venv/lib/python3.12/site-packages/telegram/_bot.py", line 4611, in get_updates
    await self._post(
  File "/root/akm_bot/venv/lib/python3.12/site-packages/telegram/_bot.py", line 698, in _post
    return await self._do_post(
           ^^^^^^^^^^^^^^^^^^^^
  File "/root/akm_bot/venv/lib/python3.12/site-packages/telegram/ext/_extbot.py", line 370, in _do_post
    return await super()._do_post(
           ^^^^^^^^^^^^^^^^^^^^^^^
  File "/root/akm_bot/venv/lib/python3.12/site-packages/telegram/_bot.py", line 727, in _do_post
    result = await request.post(
             ^^^^^^^^^^^^^^^^^^^
  File "/root/akm_bot/venv/lib/python3.12/site-packages/telegram/request/_baserequest.py", line 197, in post
    result = await self._request_wrapper(
             ^^^^^^^^^^^^^^^^^^^^^^^^^^^^
  File "/root/akm_bot/venv/lib/python3.12/site-packages/telegram/request/_baserequest.py", line 374, in _request_wrapper
    raise exception
telegram.error.Conflict: Conflict: terminated by other getUpdates request; make sure that only one bot instance is running
2025-08-07 15:43:39,781 | ERROR    | __main__ | Exception while handling update None
Traceback (most recent call last):
  File "/root/akm_bot/venv/lib/python3.12/site-packages/telegram/ext/_utils/networkloop.py", line 115, in network_retry_loop
    if not await do_action():
           ^^^^^^^^^^^^^^^^^
  File "/root/akm_bot/venv/lib/python3.12/site-packages/telegram/ext/_utils/networkloop.py", line 108, in do_action
    return action_cb_task.result()
           ^^^^^^^^^^^^^^^^^^^^^^^
  File "/root/akm_bot/venv/lib/python3.12/site-packages/telegram/ext/_updater.py", line 340, in polling_action_cb
    updates = await self.bot.get_updates(
              ^^^^^^^^^^^^^^^^^^^^^^^^^^^
  File "/root/akm_bot/venv/lib/python3.12/site-packages/telegram/ext/_extbot.py", line 670, in get_updates
    updates = await super().get_updates(
              ^^^^^^^^^^^^^^^^^^^^^^^^^^
  File "/root/akm_bot/venv/lib/python3.12/site-packages/telegram/_bot.py", line 4611, in get_updates
    await self._post(
  File "/root/akm_bot/venv/lib/python3.12/site-packages/telegram/_bot.py", line 698, in _post
    return await self._do_post(
           ^^^^^^^^^^^^^^^^^^^^
  File "/root/akm_bot/venv/lib/python3.12/site-packages/telegram/ext/_extbot.py", line 370, in _do_post
    return await super()._do_post(
           ^^^^^^^^^^^^^^^^^^^^^^^
  File "/root/akm_bot/venv/lib/python3.12/site-packages/telegram/_bot.py", line 727, in _do_post
    result = await request.post(
             ^^^^^^^^^^^^^^^^^^^
  File "/root/akm_bot/venv/lib/python3.12/site-packages/telegram/request/_baserequest.py", line 197, in post
    result = await self._request_wrapper(
             ^^^^^^^^^^^^^^^^^^^^^^^^^^^^
  File "/root/akm_bot/venv/lib/python3.12/site-packages/telegram/request/_baserequest.py", line 374, in _request_wrapper
    raise exception
telegram.error.Conflict: Conflict: terminated by other getUpdates request; make sure that only one bot instance is running
2025-08-07 15:43:47,541 | ERROR    | __main__ | Exception while handling update None
Traceback (most recent call last):
  File "/root/akm_bot/venv/lib/python3.12/site-packages/telegram/ext/_utils/networkloop.py", line 115, in network_retry_loop
    if not await do_action():
           ^^^^^^^^^^^^^^^^^
  File "/root/akm_bot/venv/lib/python3.12/site-packages/telegram/ext/_utils/networkloop.py", line 108, in do_action
    return action_cb_task.result()
           ^^^^^^^^^^^^^^^^^^^^^^^
  File "/root/akm_bot/venv/lib/python3.12/site-packages/telegram/ext/_updater.py", line 340, in polling_action_cb
    updates = await self.bot.get_updates(
              ^^^^^^^^^^^^^^^^^^^^^^^^^^^
  File "/root/akm_bot/venv/lib/python3.12/site-packages/telegram/ext/_extbot.py", line 670, in get_updates
    updates = await super().get_updates(
              ^^^^^^^^^^^^^^^^^^^^^^^^^^
  File "/root/akm_bot/venv/lib/python3.12/site-packages/telegram/_bot.py", line 4611, in get_updates
    await self._post(
  File "/root/akm_bot/venv/lib/python3.12/site-packages/telegram/_bot.py", line 698, in _post
    return await self._do_post(
           ^^^^^^^^^^^^^^^^^^^^
  File "/root/akm_bot/venv/lib/python3.12/site-packages/telegram/ext/_extbot.py", line 370, in _do_post
    return await super()._do_post(
           ^^^^^^^^^^^^^^^^^^^^^^^
  File "/root/akm_bot/venv/lib/python3.12/site-packages/telegram/_bot.py", line 727, in _do_post
    result = await request.post(
             ^^^^^^^^^^^^^^^^^^^
  File "/root/akm_bot/venv/lib/python3.12/site-packages/telegram/request/_baserequest.py", line 197, in post
    result = await self._request_wrapper(
             ^^^^^^^^^^^^^^^^^^^^^^^^^^^^
  File "/root/akm_bot/venv/lib/python3.12/site-packages/telegram/request/_baserequest.py", line 374, in _request_wrapper
    raise exception
telegram.error.Conflict: Conflict: terminated by other getUpdates request; make sure that only one bot instance is running
2025-08-07 15:43:51,597 | ERROR    | __main__ | Exception while handling update None
Traceback (most recent call last):
  File "/root/akm_bot/venv/lib/python3.12/site-packages/telegram/ext/_utils/networkloop.py", line 115, in network_retry_loop
    if not await do_action():
           ^^^^^^^^^^^^^^^^^
  File "/root/akm_bot/venv/lib/python3.12/site-packages/telegram/ext/_utils/networkloop.py", line 108, in do_action
    return action_cb_task.result()
           ^^^^^^^^^^^^^^^^^^^^^^^
  File "/root/akm_bot/venv/lib/python3.12/site-packages/telegram/ext/_updater.py", line 340, in polling_action_cb
    updates = await self.bot.get_updates(
              ^^^^^^^^^^^^^^^^^^^^^^^^^^^
  File "/root/akm_bot/venv/lib/python3.12/site-packages/telegram/ext/_extbot.py", line 670, in get_updates
    updates = await super().get_updates(
              ^^^^^^^^^^^^^^^^^^^^^^^^^^
  File "/root/akm_bot/venv/lib/python3.12/site-packages/telegram/_bot.py", line 4611, in get_updates
    await self._post(
  File "/root/akm_bot/venv/lib/python3.12/site-packages/telegram/_bot.py", line 698, in _post
    return await self._do_post(
           ^^^^^^^^^^^^^^^^^^^^
  File "/root/akm_bot/venv/lib/python3.12/site-packages/telegram/ext/_extbot.py", line 370, in _do_post
    return await super()._do_post(
           ^^^^^^^^^^^^^^^^^^^^^^^
  File "/root/akm_bot/venv/lib/python3.12/site-packages/telegram/_bot.py", line 727, in _do_post
    result = await request.post(
             ^^^^^^^^^^^^^^^^^^^
  File "/root/akm_bot/venv/lib/python3.12/site-packages/telegram/request/_baserequest.py", line 197, in post
    result = await self._request_wrapper(
             ^^^^^^^^^^^^^^^^^^^^^^^^^^^^
  File "/root/akm_bot/venv/lib/python3.12/site-packages/telegram/request/_baserequest.py", line 374, in _request_wrapper
    raise exception
telegram.error.Conflict: Conflict: terminated by other getUpdates request; make sure that only one bot instance is running
2025-08-07 15:44:03,165 | ERROR    | __main__ | Exception while handling update None
Traceback (most recent call last):
  File "/root/akm_bot/venv/lib/python3.12/site-packages/telegram/ext/_utils/networkloop.py", line 115, in network_retry_loop
    if not await do_action():
           ^^^^^^^^^^^^^^^^^
  File "/root/akm_bot/venv/lib/python3.12/site-packages/telegram/ext/_utils/networkloop.py", line 108, in do_action
    return action_cb_task.result()
           ^^^^^^^^^^^^^^^^^^^^^^^
  File "/root/akm_bot/venv/lib/python3.12/site-packages/telegram/ext/_updater.py", line 340, in polling_action_cb
    updates = await self.bot.get_updates(
              ^^^^^^^^^^^^^^^^^^^^^^^^^^^
  File "/root/akm_bot/venv/lib/python3.12/site-packages/telegram/ext/_extbot.py", line 670, in get_updates
    updates = await super().get_updates(
              ^^^^^^^^^^^^^^^^^^^^^^^^^^
  File "/root/akm_bot/venv/lib/python3.12/site-packages/telegram/_bot.py", line 4611, in get_updates
    await self._post(
  File "/root/akm_bot/venv/lib/python3.12/site-packages/telegram/_bot.py", line 698, in _post
    return await self._do_post(
           ^^^^^^^^^^^^^^^^^^^^
  File "/root/akm_bot/venv/lib/python3.12/site-packages/telegram/ext/_extbot.py", line 370, in _do_post
    return await super()._do_post(
           ^^^^^^^^^^^^^^^^^^^^^^^
  File "/root/akm_bot/venv/lib/python3.12/site-packages/telegram/_bot.py", line 727, in _do_post
    result = await request.post(
             ^^^^^^^^^^^^^^^^^^^
  File "/root/akm_bot/venv/lib/python3.12/site-packages/telegram/request/_baserequest.py", line 197, in post
    result = await self._request_wrapper(
             ^^^^^^^^^^^^^^^^^^^^^^^^^^^^
  File "/root/akm_bot/venv/lib/python3.12/site-packages/telegram/request/_baserequest.py", line 374, in _request_wrapper
    raise exception
telegram.error.Conflict: Conflict: terminated by other getUpdates request; make sure that only one bot instance is running
2025-08-07 15:44:07,224 | ERROR    | __main__ | Exception while handling update None
Traceback (most recent call last):
  File "/root/akm_bot/venv/lib/python3.12/site-packages/telegram/ext/_utils/networkloop.py", line 115, in network_retry_loop
    if not await do_action():
           ^^^^^^^^^^^^^^^^^
  File "/root/akm_bot/venv/lib/python3.12/site-packages/telegram/ext/_utils/networkloop.py", line 108, in do_action
    return action_cb_task.result()
           ^^^^^^^^^^^^^^^^^^^^^^^
  File "/root/akm_bot/venv/lib/python3.12/site-packages/telegram/ext/_updater.py", line 340, in polling_action_cb
    updates = await self.bot.get_updates(
              ^^^^^^^^^^^^^^^^^^^^^^^^^^^
  File "/root/akm_bot/venv/lib/python3.12/site-packages/telegram/ext/_extbot.py", line 670, in get_updates
    updates = await super().get_updates(
              ^^^^^^^^^^^^^^^^^^^^^^^^^^
  File "/root/akm_bot/venv/lib/python3.12/site-packages/telegram/_bot.py", line 4611, in get_updates
    await self._post(
  File "/root/akm_bot/venv/lib/python3.12/site-packages/telegram/_bot.py", line 698, in _post
    return await self._do_post(
           ^^^^^^^^^^^^^^^^^^^^
  File "/root/akm_bot/venv/lib/python3.12/site-packages/telegram/ext/_extbot.py", line 370, in _do_post
    return await super()._do_post(
           ^^^^^^^^^^^^^^^^^^^^^^^
  File "/root/akm_bot/venv/lib/python3.12/site-packages/telegram/_bot.py", line 727, in _do_post
    result = await request.post(
             ^^^^^^^^^^^^^^^^^^^
  File "/root/akm_bot/venv/lib/python3.12/site-packages/telegram/request/_baserequest.py", line 197, in post
    result = await self._request_wrapper(
             ^^^^^^^^^^^^^^^^^^^^^^^^^^^^
  File "/root/akm_bot/venv/lib/python3.12/site-packages/telegram/request/_baserequest.py", line 374, in _request_wrapper
    raise exception
telegram.error.Conflict: Conflict: terminated by other getUpdates request; make sure that only one bot instance is running
2025-08-07 15:44:24,481 | ERROR    | __main__ | Exception while handling update None
Traceback (most recent call last):
  File "/root/akm_bot/venv/lib/python3.12/site-packages/telegram/ext/_utils/networkloop.py", line 115, in network_retry_loop
    if not await do_action():
           ^^^^^^^^^^^^^^^^^
  File "/root/akm_bot/venv/lib/python3.12/site-packages/telegram/ext/_utils/networkloop.py", line 108, in do_action
    return action_cb_task.result()
           ^^^^^^^^^^^^^^^^^^^^^^^
  File "/root/akm_bot/venv/lib/python3.12/site-packages/telegram/ext/_updater.py", line 340, in polling_action_cb
    updates = await self.bot.get_updates(
              ^^^^^^^^^^^^^^^^^^^^^^^^^^^
  File "/root/akm_bot/venv/lib/python3.12/site-packages/telegram/ext/_extbot.py", line 670, in get_updates
    updates = await super().get_updates(
              ^^^^^^^^^^^^^^^^^^^^^^^^^^
  File "/root/akm_bot/venv/lib/python3.12/site-packages/telegram/_bot.py", line 4611, in get_updates
    await self._post(
  File "/root/akm_bot/venv/lib/python3.12/site-packages/telegram/_bot.py", line 698, in _post
    return await self._do_post(
           ^^^^^^^^^^^^^^^^^^^^
  File "/root/akm_bot/venv/lib/python3.12/site-packages/telegram/ext/_extbot.py", line 370, in _do_post
    return await super()._do_post(
           ^^^^^^^^^^^^^^^^^^^^^^^
  File "/root/akm_bot/venv/lib/python3.12/site-packages/telegram/_bot.py", line 727, in _do_post
    result = await request.post(
             ^^^^^^^^^^^^^^^^^^^
  File "/root/akm_bot/venv/lib/python3.12/site-packages/telegram/request/_baserequest.py", line 197, in post
    result = await self._request_wrapper(
             ^^^^^^^^^^^^^^^^^^^^^^^^^^^^
  File "/root/akm_bot/venv/lib/python3.12/site-packages/telegram/request/_baserequest.py", line 374, in _request_wrapper
    raise exception
telegram.error.Conflict: Conflict: terminated by other getUpdates request; make sure that only one bot instance is running
2025-08-07 15:44:28,538 | ERROR    | __main__ | Exception while handling update None
Traceback (most recent call last):
  File "/root/akm_bot/venv/lib/python3.12/site-packages/telegram/ext/_utils/networkloop.py", line 115, in network_retry_loop
    if not await do_action():
           ^^^^^^^^^^^^^^^^^
  File "/root/akm_bot/venv/lib/python3.12/site-packages/telegram/ext/_utils/networkloop.py", line 108, in do_action
    return action_cb_task.result()
           ^^^^^^^^^^^^^^^^^^^^^^^
  File "/root/akm_bot/venv/lib/python3.12/site-packages/telegram/ext/_updater.py", line 340, in polling_action_cb
    updates = await self.bot.get_updates(
              ^^^^^^^^^^^^^^^^^^^^^^^^^^^
  File "/root/akm_bot/venv/lib/python3.12/site-packages/telegram/ext/_extbot.py", line 670, in get_updates
    updates = await super().get_updates(
              ^^^^^^^^^^^^^^^^^^^^^^^^^^
  File "/root/akm_bot/venv/lib/python3.12/site-packages/telegram/_bot.py", line 4611, in get_updates
    await self._post(
  File "/root/akm_bot/venv/lib/python3.12/site-packages/telegram/_bot.py", line 698, in _post
    return await self._do_post(
           ^^^^^^^^^^^^^^^^^^^^
  File "/root/akm_bot/venv/lib/python3.12/site-packages/telegram/ext/_extbot.py", line 370, in _do_post
    return await super()._do_post(
           ^^^^^^^^^^^^^^^^^^^^^^^
  File "/root/akm_bot/venv/lib/python3.12/site-packages/telegram/_bot.py", line 727, in _do_post
    result = await request.post(
             ^^^^^^^^^^^^^^^^^^^
  File "/root/akm_bot/venv/lib/python3.12/site-packages/telegram/request/_baserequest.py", line 197, in post
    result = await self._request_wrapper(
             ^^^^^^^^^^^^^^^^^^^^^^^^^^^^
  File "/root/akm_bot/venv/lib/python3.12/site-packages/telegram/request/_baserequest.py", line 374, in _request_wrapper
    raise exception
telegram.error.Conflict: Conflict: terminated by other getUpdates request; make sure that only one bot instance is running
2025-08-07 15:44:54,360 | ERROR    | __main__ | Exception while handling update None
Traceback (most recent call last):
  File "/root/akm_bot/venv/lib/python3.12/site-packages/telegram/ext/_utils/networkloop.py", line 115, in network_retry_loop
    if not await do_action():
           ^^^^^^^^^^^^^^^^^
  File "/root/akm_bot/venv/lib/python3.12/site-packages/telegram/ext/_utils/networkloop.py", line 108, in do_action
    return action_cb_task.result()
           ^^^^^^^^^^^^^^^^^^^^^^^
  File "/root/akm_bot/venv/lib/python3.12/site-packages/telegram/ext/_updater.py", line 340, in polling_action_cb
    updates = await self.bot.get_updates(
              ^^^^^^^^^^^^^^^^^^^^^^^^^^^
  File "/root/akm_bot/venv/lib/python3.12/site-packages/telegram/ext/_extbot.py", line 670, in get_updates
    updates = await super().get_updates(
              ^^^^^^^^^^^^^^^^^^^^^^^^^^
  File "/root/akm_bot/venv/lib/python3.12/site-packages/telegram/_bot.py", line 4611, in get_updates
    await self._post(
  File "/root/akm_bot/venv/lib/python3.12/site-packages/telegram/_bot.py", line 698, in _post
    return await self._do_post(
           ^^^^^^^^^^^^^^^^^^^^
  File "/root/akm_bot/venv/lib/python3.12/site-packages/telegram/ext/_extbot.py", line 370, in _do_post
    return await super()._do_post(
           ^^^^^^^^^^^^^^^^^^^^^^^
  File "/root/akm_bot/venv/lib/python3.12/site-packages/telegram/_bot.py", line 727, in _do_post
    result = await request.post(
             ^^^^^^^^^^^^^^^^^^^
  File "/root/akm_bot/venv/lib/python3.12/site-packages/telegram/request/_baserequest.py", line 197, in post
    result = await self._request_wrapper(
             ^^^^^^^^^^^^^^^^^^^^^^^^^^^^
  File "/root/akm_bot/venv/lib/python3.12/site-packages/telegram/request/_baserequest.py", line 374, in _request_wrapper
    raise exception
telegram.error.Conflict: Conflict: terminated by other getUpdates request; make sure that only one bot instance is running
2025-08-07 15:44:58,429 | ERROR    | __main__ | Exception while handling update None
Traceback (most recent call last):
  File "/root/akm_bot/venv/lib/python3.12/site-packages/telegram/ext/_utils/networkloop.py", line 115, in network_retry_loop
    if not await do_action():
           ^^^^^^^^^^^^^^^^^
  File "/root/akm_bot/venv/lib/python3.12/site-packages/telegram/ext/_utils/networkloop.py", line 108, in do_action
    return action_cb_task.result()
           ^^^^^^^^^^^^^^^^^^^^^^^
  File "/root/akm_bot/venv/lib/python3.12/site-packages/telegram/ext/_updater.py", line 340, in polling_action_cb
    updates = await self.bot.get_updates(
              ^^^^^^^^^^^^^^^^^^^^^^^^^^^
  File "/root/akm_bot/venv/lib/python3.12/site-packages/telegram/ext/_extbot.py", line 670, in get_updates
    updates = await super().get_updates(
              ^^^^^^^^^^^^^^^^^^^^^^^^^^
  File "/root/akm_bot/venv/lib/python3.12/site-packages/telegram/_bot.py", line 4611, in get_updates
    await self._post(
  File "/root/akm_bot/venv/lib/python3.12/site-packages/telegram/_bot.py", line 698, in _post
    return await self._do_post(
           ^^^^^^^^^^^^^^^^^^^^
  File "/root/akm_bot/venv/lib/python3.12/site-packages/telegram/ext/_extbot.py", line 370, in _do_post
    return await super()._do_post(
           ^^^^^^^^^^^^^^^^^^^^^^^
  File "/root/akm_bot/venv/lib/python3.12/site-packages/telegram/_bot.py", line 727, in _do_post
    result = await request.post(
             ^^^^^^^^^^^^^^^^^^^
  File "/root/akm_bot/venv/lib/python3.12/site-packages/telegram/request/_baserequest.py", line 197, in post
    result = await self._request_wrapper(
             ^^^^^^^^^^^^^^^^^^^^^^^^^^^^
  File "/root/akm_bot/venv/lib/python3.12/site-packages/telegram/request/_baserequest.py", line 374, in _request_wrapper
    raise exception
telegram.error.Conflict: Conflict: terminated by other getUpdates request; make sure that only one bot instance is running
2025-08-07 15:45:28,623 | ERROR    | __main__ | Exception while handling update None
Traceback (most recent call last):
  File "/root/akm_bot/venv/lib/python3.12/site-packages/telegram/ext/_utils/networkloop.py", line 115, in network_retry_loop
    if not await do_action():
           ^^^^^^^^^^^^^^^^^
  File "/root/akm_bot/venv/lib/python3.12/site-packages/telegram/ext/_utils/networkloop.py", line 108, in do_action
    return action_cb_task.result()
           ^^^^^^^^^^^^^^^^^^^^^^^
  File "/root/akm_bot/venv/lib/python3.12/site-packages/telegram/ext/_updater.py", line 340, in polling_action_cb
    updates = await self.bot.get_updates(
              ^^^^^^^^^^^^^^^^^^^^^^^^^^^
  File "/root/akm_bot/venv/lib/python3.12/site-packages/telegram/ext/_extbot.py", line 670, in get_updates
    updates = await super().get_updates(
              ^^^^^^^^^^^^^^^^^^^^^^^^^^
  File "/root/akm_bot/venv/lib/python3.12/site-packages/telegram/_bot.py", line 4611, in get_updates
    await self._post(
  File "/root/akm_bot/venv/lib/python3.12/site-packages/telegram/_bot.py", line 698, in _post
    return await self._do_post(
           ^^^^^^^^^^^^^^^^^^^^
  File "/root/akm_bot/venv/lib/python3.12/site-packages/telegram/ext/_extbot.py", line 370, in _do_post
    return await super()._do_post(
           ^^^^^^^^^^^^^^^^^^^^^^^
  File "/root/akm_bot/venv/lib/python3.12/site-packages/telegram/_bot.py", line 727, in _do_post
    result = await request.post(
             ^^^^^^^^^^^^^^^^^^^
  File "/root/akm_bot/venv/lib/python3.12/site-packages/telegram/request/_baserequest.py", line 197, in post
    result = await self._request_wrapper(
             ^^^^^^^^^^^^^^^^^^^^^^^^^^^^
  File "/root/akm_bot/venv/lib/python3.12/site-packages/telegram/request/_baserequest.py", line 374, in _request_wrapper
    raise exception
telegram.error.Conflict: Conflict: terminated by other getUpdates request; make sure that only one bot instance is running
2025-08-07 15:45:32,680 | ERROR    | __main__ | Exception while handling update None
Traceback (most recent call last):
  File "/root/akm_bot/venv/lib/python3.12/site-packages/telegram/ext/_utils/networkloop.py", line 115, in network_retry_loop
    if not await do_action():
           ^^^^^^^^^^^^^^^^^
  File "/root/akm_bot/venv/lib/python3.12/site-packages/telegram/ext/_utils/networkloop.py", line 108, in do_action
    return action_cb_task.result()
           ^^^^^^^^^^^^^^^^^^^^^^^
  File "/root/akm_bot/venv/lib/python3.12/site-packages/telegram/ext/_updater.py", line 340, in polling_action_cb
    updates = await self.bot.get_updates(
              ^^^^^^^^^^^^^^^^^^^^^^^^^^^
  File "/root/akm_bot/venv/lib/python3.12/site-packages/telegram/ext/_extbot.py", line 670, in get_updates
    updates = await super().get_updates(
              ^^^^^^^^^^^^^^^^^^^^^^^^^^
  File "/root/akm_bot/venv/lib/python3.12/site-packages/telegram/_bot.py", line 4611, in get_updates
    await self._post(
  File "/root/akm_bot/venv/lib/python3.12/site-packages/telegram/_bot.py", line 698, in _post
    return await self._do_post(
           ^^^^^^^^^^^^^^^^^^^^
  File "/root/akm_bot/venv/lib/python3.12/site-packages/telegram/ext/_extbot.py", line 370, in _do_post
    return await super()._do_post(
           ^^^^^^^^^^^^^^^^^^^^^^^
  File "/root/akm_bot/venv/lib/python3.12/site-packages/telegram/_bot.py", line 727, in _do_post
    result = await request.post(
             ^^^^^^^^^^^^^^^^^^^
  File "/root/akm_bot/venv/lib/python3.12/site-packages/telegram/request/_baserequest.py", line 197, in post
    result = await self._request_wrapper(
             ^^^^^^^^^^^^^^^^^^^^^^^^^^^^
  File "/root/akm_bot/venv/lib/python3.12/site-packages/telegram/request/_baserequest.py", line 374, in _request_wrapper
    raise exception
telegram.error.Conflict: Conflict: terminated by other getUpdates request; make sure that only one bot instance is running
2025-08-07 15:45:46,789 | ERROR    | asyncio | Task was destroyed but it is pending!
task: <Task pending name='Updater:start_polling:polling_task' coro=<network_retry_loop() running at /root/akm_bot/venv/lib/python3.12/site-packages/telegram/ext/_utils/networkloop.py:153> wait_for=<Future pending cb=[Task.task_wakeup()]> cb=[Task.task_wakeup()]>
2025-08-07 15:45:46,789 | ERROR    | asyncio | Task was destroyed but it is pending!
task: <Task pending name='Application:8184892967:update_fetcher' coro=<Application._update_fetcher() running at /root/akm_bot/venv/lib/python3.12/site-packages/telegram/ext/_application.py:1228> wait_for=<Future pending cb=[Task.task_wakeup()]>>
2025-08-07 15:49:37,292 | INFO     | __main__ | üöÄ –ë–æ—Ç –∑–∞–ø—É—â–µ–Ω‚Ä¶
2025-08-07 15:49:58,823 | INFO     | __main__ | –ó–∞—è–≤–∫–∞ output/form_1169418620_20250807154957.pdf –æ—Ç–ø—Ä–∞–≤–ª–µ–Ω–∞
2025-08-07 16:12:26,869 | INFO     | __main__ | üöÄ –ë–æ—Ç –∑–∞–ø—É—â–µ–Ω‚Ä¶
2025-08-07 16:16:09,523 | INFO     | __main__ | –ó–∞—è–≤–∫–∞ output/form_1169418620_20250807161608.pdf –æ—Ç–ø—Ä–∞–≤–ª–µ–Ω–∞
2025-08-07 16:23:08,139 | INFO     | __main__ | üöÄ –ë–æ—Ç –∑–∞–ø—É—â–µ–Ω‚Ä¶
2025-08-07 16:24:04,598 | WARNING  | __main__ | [ACCESS DENIED] 491526969
2025-08-07 16:24:35,879 | WARNING  | __main__ | [ACCESS DENIED] 491526969
2025-08-07 16:24:42,587 | WARNING  | __main__ | [ACCESS DENIED] 491526969
2025-08-07 16:48:33,457 | INFO     | __main__ | üöÄ –ë–æ—Ç –∑–∞–ø—É—â–µ–Ω‚Ä¶
2025-08-07 16:49:03,090 | ERROR    | __main__ | Exception while handling update Update(message=Message(channel_chat_created=False, chat=Chat(first_name='No?', id=1169418620, last_name='Where?', type=<ChatType.PRIVATE>, username='nekodro4'), date=datetime.datetime(2025, 8, 7, 16, 49, 3, tzinfo=datetime.timezone.utc), delete_chat_photo=False, from_user=User(first_name='No?', id=1169418620, is_bot=False, language_code='ru', last_name='Where?', username='nekodro4'), group_chat_created=False, message_id=142, supergroup_chat_created=False, web_app_data=WebAppData(button_text='üìù –û—Ñ–æ—Ä–º–∏—Ç—å –∑–∞—è–≤–∫—É', data='{"date":"2025-08-07","time_range":"10:00 - 18:00","company":"–û–û–û \\"–î–µ–ª–æ–≤—ã–µ –ª–∏–Ω–∏–∏\\"","cargo":"–ü–ª–µ–Ω–∫–∞ –≤ —Ä—É–ª–æ–Ω–∞—Ö","cargo_count":4,"car_model":"23123","car_plate":"A111AA11","person":"123123","use_lift":true,"materials_in":true,"unloading_small":true,"loading_small":true,"agree":"on","materials_out":false,"unloading_big":false,"loading_big":false}')), update_id=680449780)
Traceback (most recent call last):
  File "/root/akm_bot/venv/lib/python3.12/site-packages/telegram/ext/_application.py", line 1311, in process_update
    await coroutine
  File "/root/akm_bot/venv/lib/python3.12/site-packages/telegram/ext/_handlers/basehandler.py", line 158, in handle_update
    return await self.callback(update, context)
           ^^^^^^^^^^^^^^^^^^^^^^^^^^^^^^^^^^^^
  File "/root/akm_bot/bot.py", line 74, in handle_web_app_data
    if 'date' in data:
                 ^^^^
UnboundLocalError: cannot access local variable 'data' where it is not associated with a value
2025-08-07 16:51:28,872 | INFO     | __main__ | üöÄ –ë–æ—Ç –∑–∞–ø—É—â–µ–Ω‚Ä¶
2025-08-07 16:51:46,297 | INFO     | __main__ | –ó–∞—è–≤–∫–∞ output/form_1169418620_20250807165145.pdf –æ—Ç–ø—Ä–∞–≤–ª–µ–Ω–∞
2025-08-07 17:09:45,116 | INFO     | __main__ | üöÄ –ë–æ—Ç –∑–∞–ø—É—â–µ–Ω‚Ä¶
2025-08-07 17:09:45,515 | ERROR    | __main__ | Exception while handling update None
Traceback (most recent call last):
  File "/root/akm_bot/venv/lib/python3.12/site-packages/telegram/ext/_utils/networkloop.py", line 115, in network_retry_loop
    if not await do_action():
           ^^^^^^^^^^^^^^^^^
  File "/root/akm_bot/venv/lib/python3.12/site-packages/telegram/ext/_utils/networkloop.py", line 108, in do_action
    return action_cb_task.result()
           ^^^^^^^^^^^^^^^^^^^^^^^
  File "/root/akm_bot/venv/lib/python3.12/site-packages/telegram/ext/_updater.py", line 340, in polling_action_cb
    updates = await self.bot.get_updates(
              ^^^^^^^^^^^^^^^^^^^^^^^^^^^
  File "/root/akm_bot/venv/lib/python3.12/site-packages/telegram/ext/_extbot.py", line 670, in get_updates
    updates = await super().get_updates(
              ^^^^^^^^^^^^^^^^^^^^^^^^^^
  File "/root/akm_bot/venv/lib/python3.12/site-packages/telegram/_bot.py", line 4611, in get_updates
    await self._post(
  File "/root/akm_bot/venv/lib/python3.12/site-packages/telegram/_bot.py", line 698, in _post
    return await self._do_post(
           ^^^^^^^^^^^^^^^^^^^^
  File "/root/akm_bot/venv/lib/python3.12/site-packages/telegram/ext/_extbot.py", line 370, in _do_post
    return await super()._do_post(
           ^^^^^^^^^^^^^^^^^^^^^^^
  File "/root/akm_bot/venv/lib/python3.12/site-packages/telegram/_bot.py", line 727, in _do_post
    result = await request.post(
             ^^^^^^^^^^^^^^^^^^^
  File "/root/akm_bot/venv/lib/python3.12/site-packages/telegram/request/_baserequest.py", line 197, in post
    result = await self._request_wrapper(
             ^^^^^^^^^^^^^^^^^^^^^^^^^^^^
  File "/root/akm_bot/venv/lib/python3.12/site-packages/telegram/request/_baserequest.py", line 374, in _request_wrapper
    raise exception
telegram.error.Conflict: Conflict: terminated by other getUpdates request; make sure that only one bot instance is running
2025-08-07 17:09:49,571 | ERROR    | __main__ | Exception while handling update None
Traceback (most recent call last):
  File "/root/akm_bot/venv/lib/python3.12/site-packages/telegram/ext/_utils/networkloop.py", line 115, in network_retry_loop
    if not await do_action():
           ^^^^^^^^^^^^^^^^^
  File "/root/akm_bot/venv/lib/python3.12/site-packages/telegram/ext/_utils/networkloop.py", line 108, in do_action
    return action_cb_task.result()
           ^^^^^^^^^^^^^^^^^^^^^^^
  File "/root/akm_bot/venv/lib/python3.12/site-packages/telegram/ext/_updater.py", line 340, in polling_action_cb
    updates = await self.bot.get_updates(
              ^^^^^^^^^^^^^^^^^^^^^^^^^^^
  File "/root/akm_bot/venv/lib/python3.12/site-packages/telegram/ext/_extbot.py", line 670, in get_updates
    updates = await super().get_updates(
              ^^^^^^^^^^^^^^^^^^^^^^^^^^
  File "/root/akm_bot/venv/lib/python3.12/site-packages/telegram/_bot.py", line 4611, in get_updates
    await self._post(
  File "/root/akm_bot/venv/lib/python3.12/site-packages/telegram/_bot.py", line 698, in _post
    return await self._do_post(
           ^^^^^^^^^^^^^^^^^^^^
  File "/root/akm_bot/venv/lib/python3.12/site-packages/telegram/ext/_extbot.py", line 370, in _do_post
    return await super()._do_post(
           ^^^^^^^^^^^^^^^^^^^^^^^
  File "/root/akm_bot/venv/lib/python3.12/site-packages/telegram/_bot.py", line 727, in _do_post
    result = await request.post(
             ^^^^^^^^^^^^^^^^^^^
  File "/root/akm_bot/venv/lib/python3.12/site-packages/telegram/request/_baserequest.py", line 197, in post
    result = await self._request_wrapper(
             ^^^^^^^^^^^^^^^^^^^^^^^^^^^^
  File "/root/akm_bot/venv/lib/python3.12/site-packages/telegram/request/_baserequest.py", line 374, in _request_wrapper
    raise exception
telegram.error.Conflict: Conflict: terminated by other getUpdates request; make sure that only one bot instance is running
2025-08-07 17:09:50,633 | ERROR    | __main__ | Exception while handling update None
Traceback (most recent call last):
  File "/root/akm_bot/venv/lib/python3.12/site-packages/telegram/ext/_utils/networkloop.py", line 115, in network_retry_loop
    if not await do_action():
           ^^^^^^^^^^^^^^^^^
  File "/root/akm_bot/venv/lib/python3.12/site-packages/telegram/ext/_utils/networkloop.py", line 108, in do_action
    return action_cb_task.result()
           ^^^^^^^^^^^^^^^^^^^^^^^
  File "/root/akm_bot/venv/lib/python3.12/site-packages/telegram/ext/_updater.py", line 340, in polling_action_cb
    updates = await self.bot.get_updates(
              ^^^^^^^^^^^^^^^^^^^^^^^^^^^
  File "/root/akm_bot/venv/lib/python3.12/site-packages/telegram/ext/_extbot.py", line 670, in get_updates
    updates = await super().get_updates(
              ^^^^^^^^^^^^^^^^^^^^^^^^^^
  File "/root/akm_bot/venv/lib/python3.12/site-packages/telegram/_bot.py", line 4611, in get_updates
    await self._post(
  File "/root/akm_bot/venv/lib/python3.12/site-packages/telegram/_bot.py", line 698, in _post
    return await self._do_post(
           ^^^^^^^^^^^^^^^^^^^^
  File "/root/akm_bot/venv/lib/python3.12/site-packages/telegram/ext/_extbot.py", line 370, in _do_post
    return await super()._do_post(
           ^^^^^^^^^^^^^^^^^^^^^^^
  File "/root/akm_bot/venv/lib/python3.12/site-packages/telegram/_bot.py", line 727, in _do_post
    result = await request.post(
             ^^^^^^^^^^^^^^^^^^^
  File "/root/akm_bot/venv/lib/python3.12/site-packages/telegram/request/_baserequest.py", line 197, in post
    result = await self._request_wrapper(
             ^^^^^^^^^^^^^^^^^^^^^^^^^^^^
  File "/root/akm_bot/venv/lib/python3.12/site-packages/telegram/request/_baserequest.py", line 374, in _request_wrapper
    raise exception
telegram.error.Conflict: Conflict: terminated by other getUpdates request; make sure that only one bot instance is running
2025-08-07 17:10:57,737 | INFO     | __main__ | üöÄ –ë–æ—Ç –∑–∞–ø—É—â–µ–Ω‚Ä¶
2025-08-07 17:11:29,490 | INFO     | __main__ | –ó–∞—è–≤–∫–∞ output/form_1169418620_20250807171128.pdf –æ—Ç–ø—Ä–∞–≤–ª–µ–Ω–∞
2025-08-07 17:13:51,221 | INFO     | __main__ | üöÄ –ë–æ—Ç –∑–∞–ø—É—â–µ–Ω‚Ä¶
2025-08-07 17:25:45,476 | INFO     | __main__ | üöÄ –ë–æ—Ç –∑–∞–ø—É—â–µ–Ω‚Ä¶
